const asyncHandler = (requestHandler) => {
  return (req, res, next) => {
    Promise.resolve(requestHandler(req, res, next)).catch((err) => next(err));
  };
};

export { asyncHandler };

// Another method to handle async errors is to use a try-catch block in the route handler itself
// and call next(err) in the catch block. This is a more traditional approach but can lead to repetitive code.

// const asyncHandler = (fn) => async (req, res, next) => {
//     try {
//         await fn(req, res, next)
//     } catch (error) {
//         res.status(err.code || 500).json({
//             success: false,
//             message: err.message
//         })
//     }
// }
